Workbook

Sheet data
G1: Holdings | H1: nel sales | I1: valuation changes
A2: country | B2: country_code | C2: date | D2: for_lt_total_pos | E2: for_lt_total_net | F2: for_lt_total_valchg | G2: for_lt_treas_pos | H2: for_lt_treas_net | I2: for_lt_treas_valchg | J2: for_lt_agcy_pos | K2: for_lt_agcy_net | L2: for_lt_agcy_valchg | M2: for_lt_corp_pos | N2: for_lt_corp_net | O2: for_lt_corp_valchg | P2: for_lt_eqty_pos | Q2: for_lt_eqty_net | R2: for_lt_eqty_valchg | S2: treasuries_stock_usd | T2: equities_stock_usd
A3: Japan | B3: 42609 | C3: 43861 | D3: 2372970 | G3: 1147586 | J3: 305664 | M3: 277666 | P3: 642054 | S3: 1147.586 | T3: 642.054
A4: Japan | B4: 42609 | C4: 43890 | D4: 2383523 | G4: 1202367 | J4: 310621 | M4: 279199 | P4: 591336 | S4: 1202.367 | T4: 591.336
A5: Japan | B5: 42609 | C5: 43921 | D5: 2340722 | G5: 1211747 | J5: 322108 | M5: 277159 | P5: 529708 | S5: 1211.747 | T5: 529.708
A6: Japan | B6: 42609 | C6: 43951 | D6: 2423361 | G6: 1202355 | J6: 319937 | M6: 294658 | P6: 606411 | S6: 1202.355 | T6: 606.411
A7: Japan | B7: 42609 | C7: 43982 | D7: 2461811 | G7: 1193317 | J7: 311615 | M7: 306764 | P7: 650115 | S7: 1193.317 | T7: 650.115
A8: Japan | B8: 42609 | C8: 44012 | D8: 2480775 | G8: 1194934 | J8: 308203 | M8: 311174 | P8: 666464 | S8: 1194.934 | T8: 666.464
A9: Japan | B9: 42609 | C9: 44043 | D9: 2567622 | G9: 1225897 | J9: 309610 | M9: 316792 | P9: 715323 | S9: 1225.897 | T9: 715.323
A10: Japan | B10: 42609 | C10: 44074 | D10: 2583596 | G10: 1210275 | J10: 300534 | M10: 316586 | P10: 756201 | S10: 1210.275 | T10: 756.201
A11: Japan | B11: 42609 | C11: 44104 | D11: 2556410 | G11: 1208762 | J11: 305069 | M11: 312109 | P11: 730470 | S11: 1208.762 | T11: 730.47
A12: Japan | B12: 42609 | C12: 44135 | D12: 2537549 | G12: 1205240 | J12: 305638 | M12: 312442 | P12: 714229 | S12: 1205.24 | T12: 714.229
A13: Japan | B13: 42609 | C13: 44165 | D13: 2600898 | G13: 1193190 | J13: 303509 | M13: 320144 | P13: 784055 | S13: 1193.19 | T13: 784.055
A14: Japan | B14: 42609 | C14: 44196 | D14: 2614130 | G14: 1184556 | J14: 308033 | M14: 317186 | P14: 804355 | S14: 1184.556 | T14: 804.355
... A39: Japan | B39: 42609 | C39: 44957 | D39: 2392112 | G39: 1029966 | J39: 255139 | M39: 302333 | P39: 804674 | S39: 1029.966 | T39: 804.674
A40: Japan | B40: 42609 | C40: 44985 | D40: 2337937 | E40: 4234 | F40: -58007 | G40: 1013830 | H40: 4458 | I40: -15677 | J40: 251696 | K40: 3326 | L40: -6241 | M40: 301466 | N40: 9712 | O40: -13427 | P40: 770945 | Q40: -13262 | R40: -22662 | S40: 1013.83 | T40: 770.945
A41: Japan | B41: 42609 | C41: 45016 | D41: 2381403 | E41: -10332 | F41: 49674 | G41: 1021979 | H41: -16470 | I41: 21569 | J41: 257480 | K41: 917 | L41: 4648 | M41: 308040 | N41: 422 | O41: 5960 | P41: 793904 | Q41: 4799 | R41: 17497 | S41: 1021.979 | T41: 793.904
A42: Japan | B42: 42609 | C42: 45046 | D42: 2427427 | E42: 33605 | F42: 11874 | G42: 1062312 | H42: 35588 | I42: 4354 | J42: 256706 | K42: -1129 | L42: 712 | M42: 309508 | N42: 1166 | O42: -136 | P42: 798901 | Q42: -2020 | R42: 6944 | S42: 1062.312 | T42: 798.901
A43: Japan | B43: 42609 | C43: 45077 | D43: 2397312 | E43: -9246 | F43: -19739 | G43: 1039875 | H43: -7992 | I43: -13860 | J43: 256575 | K43: 2115 | L43: -1859 | M43: 306149 | N43: 1811 | O43: -4535 | P43: 794713 | Q43: -5180 | R43: 515 | S43: 1039.875 | T43: 794.713
A44: Japan | B44: 42609 | C44: 45107 | D44: 2429315 | E44: 6121 | F44: 27433 | G44: 1035798 | H44: 1633 | I44: -9360 | J44: 252543 | K44: 4678 | L44: -1373 | M44: 303464 | N44: 819 | O44: -2935 | P44: 837510 | Q44: -1009 | R44: 41101 | S44: 1035.798 | T44: 837.51
A45: Japan | B45: 42609 | C45: 45138 | D45: 2449127 | E45: -5068 | F45: 23752 | G45: 1036094 | H45: 3633 | I45: -5099 | J45: 253346 | K45: 977 | L45: -779 | M45: 305263 | N45: -385 | O45: 1695 | P45: 854424 | Q45: -9293 | R45: 27935 | S45: 1036.094 | T45: 854.424
A46: Japan | B46: 42609 | C46: 45169 | D46: 2435922 | E46: 10754 | F46: -24612 | G46: 1031066 | H46: 796 | I46: -4803 | J46: 252394 | K46: 1626 | L46: -2255 | M46: 314117 | N46: 11066 | O46: -2233 | P46: 838345 | Q46: -2734 | R46: -15321 | S46: 1031.066 | T46: 838.345
A47: Japan | B47: 42609 | C47: 45199 | D47: 2365952 | E47: -889 | F47: -66546 | G47: 999496 | H47: -13479 | I47: -18699 | J47: 252484 | K47: 7330 | L47: -7327 | M47: 307378 | N47: 2612 | O47: -7304 | P47: 806594 | Q47: 2648 | R47: -33216 | S47: 999.496 | T47: 806.594
A48: Japan | B48: 42609 | C48: 45230 | D48: 2343270 | E48: 15478 | F48: -35509 | G48: 1015409 | H48: 26423 | I48: -10223 | J48: 239320 | K48: -8413 | L48: -4653 | M48: 297971 | N48: -3954 | O48: -4227 | P48: 790570 | Q48: 1422 | R48: -16406 | S48: 1015.409 | T48: 790.57
A49: Japan | B49: 42609 | C49: 45260 | D49: 2453909 | E49: -1342 | F49: 116304 | G49: 1042037 | H49: -72 | I49: 31522 | J49: 251227 | K49: 1762 | L49: 10010 | M49: 310213 | N49: 456 | O49: 12259 | P49: 850432 | Q49: -3488 | R49: 62513 | S49: 1042.037 | T49: 850.432
A50: Japan | B50: 42609 | C50: 45291 | D50: 2479621 | E50: -21925 | F50: 78289 | G50: 1029295 | H50: -20070 | I50: 26322 | J50: 257988 | K50: 2707 | L50: 5640 | M50: 308930 | N50: 3176 | O50: 6836 | P50: 883408 | Q50: -7738 | R50: 39491 | S50: 1029.295 | T50: 883.408
A51: Japan | B51: 42609 | C51: 45322 | D51: 2512128 | E51: 11194 | F51: 33496 | G51: 1051432 | H51: 20322 | I51: 8114 | J51: 254127 | K51: -2247 | L51: -1031 | M51: 304564 | N51: -2287 | O51: -723 | P51: 902005 | Q51: -4594 | R51: 27136 | S51: 1051.432 | T51: 902.005
... A73: Japan | B73: 42609 | C73: 45991 | D73: 2940243 | E73: -7706 | F73: -284 | G73: 1069309 | H73: -1454 | I73: 3732 | J73: 282149 | K73: -2538 | L73: 3785 | M73: 325578 | N73: 655 | O73: -2855 | P73: 1263207 | Q73: -4369 | R73: -4946 | S73: 1069.309 | T73: 1263.207

Sheet chart
C1: =data!G1 -> Holdings | D1: =data!H1 -> nel sales | E1: =data!I1 -> valuation changes | F1: Delta Holding | G1: Net Sales + valuation sales | I1: Delta Holding | J1: nel sales | K1: valuation changes | L1: Holdings stocks (rhs)
B2: =data!C3 -> 43861 | C2: =data!G3 -> 1147586 | H2: =B2 -> 43861 | L2: =C2 -> 1147586
B3: =data!C4 -> 43890 | C3: =data!G4 -> 1202367 | F3: =C3-C2 -> 54781 | H3: =B3 -> 43890 | L3: =C3 -> 1202367
B4: =data!C5 -> 43921 | C4: =data!G5 -> 1211747 | F4: =C4-C3 -> 9380 | H4: =B4 -> 43921 | L4: =C4 -> 1211747
B5: =data!C6 -> 43951 | C5: =data!G6 -> 1202355 | F5: =C5-C4 -> -9392 | H5: =B5 -> 43951 | L5: =C5 -> 1202355
B6: =data!C7 -> 43982 | C6: =data!G7 -> 1193317 | F6: =C6-C5 -> -9038 | H6: =B6 -> 43982 | L6: =C6 -> 1193317
B7: =data!C8 -> 44012 | C7: =data!G8 -> 1194934 | F7: =C7-C6 -> 1617 | H7: =B7 -> 44012 | L7: =C7 -> 1194934
B8: =data!C9 -> 44043 | C8: =data!G9 -> 1225897 | F8: =C8-C7 -> 30963 | H8: =B8 -> 44043 | L8: =C8 -> 1225897
B9: =data!C10 -> 44074 | C9: =data!G10 -> 1210275 | F9: =C9-C8 -> -15622 | H9: =B9 -> 44074 | L9: =C9 -> 1210275
B10: =data!C11 -> 44104 | C10: =data!G11 -> 1208762 | F10: =C10-C9 -> -1513 | H10: =B10 -> 44104 | L10: =C10 -> 1208762
B11: =data!C12 -> 44135 | C11: =data!G12 -> 1205240 | F11: =C11-C10 -> -3522 | H11: =B11 -> 44135 | L11: =C11 -> 1205240
B12: =data!C13 -> 44165 | C12: =data!G13 -> 1193190 | F12: =C12-C11 -> -12050 | H12: =B12 -> 44165 | L12: =C12 -> 1193190
B13: =data!C14 -> 44196 | C13: =data!G14 -> 1184556 | F13: =C13-C12 -> -8634 | H13: =B13 -> 44196 | L13: =C13 -> 1184556
B14: =data!C15 -> 44227 | C14: =data!G15 -> 1210028 | F14: =C14-C13 -> 25472 | H14: =B14 -> 44227 | I14: =C14-C2 -> 62442 | L14: =C14 -> 1210028
B15: =data!C16 -> 44255 | C15: =data!G16 -> 1187707 | F15: =C15-C14 -> -22321 | H15: =B15 -> 44255 | I15: =C15-C3 -> -14660 | L15: =C15 -> 1187707
B16: =data!C17 -> 44286 | C16: =data!G17 -> 1174075 | F16: =C16-C15 -> -13632 | H16: =B16 -> 44286 | I16: =C16-C4 -> -37672 | L16: =C16 -> 1174075
B17: =data!C18 -> 44316 | C17: =data!G18 -> 1211116 | F17: =C17-C16 -> 37041 | H17: =B17 -> 44316 | I17: =C17-C5 -> 8761 | L17: =C17 -> 1211116
B18: =data!C19 -> 44347 | C18: =data!G19 -> 1200461 | F18: =C18-C17 -> -10655 | H18: =B18 -> 44347 | I18: =C18-C6 -> 7144 | L18: =C18 -> 1200461
B19: =data!C20 -> 44377 | C19: =data!G20 -> 1214367 | F19: =C19-C18 -> 13906 | H19: =B19 -> 44377 | I19: =C19-C7 -> 19433 | L19: =C19 -> 1214367
B20: =data!C21 -> 44408 | C20: =data!G21 -> 1245237 | F20: =C20-C19 -> 30870 | H20: =B20 -> 44408 | I20: =C20-C8 -> 19340 | L20: =C20 -> 1245237
B21: =data!C22 -> 44439 | C21: =data!G22 -> 1251375 | F21: =C21-C20 -> 6138 | H21: =B21 -> 44439 | I21: =C21-C9 -> 41100 | L21: =C21 -> 1251375
B22: =data!C23 -> 44469 | C22: =data!G23 -> 1233622 | F22: =C22-C21 -> -17753 | H22: =B22 -> 44469 | I22: =C22-C10 -> 24860 | L22: =C22 -> 1233622
B23: =data!C24 -> 44500 | C23: =data!G24 -> 1243981 | F23: =C23-C22 -> 10359 | H23: =B23 -> 44500 | I23: =C23-C11 -> 38741 | L23: =C23 -> 1243981
B24: =data!C25 -> 44530 | C24: =data!G25 -> 1244343 | F24: =C24-C23 -> 362 | H24: =B24 -> 44530 | I24: =C24-C12 -> 51153 | L24: =C24 -> 1244343
B25: =data!C26 -> 44561 | C25: =data!G26 -> 1214078 | F25: =C25-C24 -> -30265 | H25: =B25 -> 44561 | I25: =C25-C13 -> 29522 | L25: =C25 -> 1214078
... B38: =data!C39 -> 44957 | C38: =data!G39 -> 1029966 | F38: =C38-C37 -> 35095 | H38: =B38 -> 44957 | I38: =C38-C26 -> -184921 | L38: =C38 -> 1029966
B39: =data!C40 -> 44985 | C39: =data!G40 -> 1013830 | D39: =data!H40 -> 4458 | E39: =data!I40 -> -15677 | F39: =C39-C38 -> -16136 | G39: =D39+E39 -> -11219 | H39: =B39 -> 44985 | I39: =C39-C27 -> -210958 | L39: =C39 -> 1013830
B40: =data!C41 -> 45016 | C40: =data!G41 -> 1021979 | D40: =data!H41 -> -16470 | E40: =data!I41 -> 21569 | F40: =C40-C39 -> 8149 | G40: =D40+E40 -> 5099 | H40: =B40 -> 45016 | I40: =C40-C28 -> -123941 | L40: =C40 -> 1021979
B41: =data!C42 -> 45046 | C41: =data!G42 -> 1062312 | D41: =data!H42 -> 35588 | E41: =data!I42 -> 4354 | F41: =C41-C40 -> 40333 | G41: =D41+E41 -> 39942 | H41: =B41 -> 45046 | I41: =C41-C29 -> -68852 | L41: =C41 -> 1062312
B42: =data!C43 -> 45077 | C42: =data!G43 -> 1039875 | D42: =data!H43 -> -7992 | E42: =data!I43 -> -13860 | F42: =C42-C41 -> -22437 | G42: =D42+E42 -> -21852 | H42: =B42 -> 45077 | I42: =C42-C30 -> -106788 | L42: =C42 -> 1039875
B43: =data!C44 -> 45107 | C43: =data!G44 -> 1035798 | D43: =data!H44 -> 1633 | E43: =data!I44 -> -9360 | F43: =C43-C42 -> -4077 | G43: =D43+E43 -> -7727 | H43: =B43 -> 45107 | I43: =C43-C31 -> -125222 | L43: =C43 -> 1035798
B44: =data!C45 -> 45138 | C44: =data!G45 -> 1036094 | D44: =data!H45 -> 3633 | E44: =data!I45 -> -5099 | F44: =C44-C43 -> 296 | G44: =D44+E44 -> -1466 | H44: =B44 -> 45138 | I44: =C44-C32 -> -116231 | L44: =C44 -> 1036094
B45: =data!C46 -> 45169 | C45: =data!G46 -> 1031066 | D45: =data!H46 -> 796 | E45: =data!I46 -> -4803 | F45: =C45-C44 -> -5028 | G45: =D45+E45 -> -4007 | H45: =B45 -> 45169 | I45: =C45-C33 -> -87267 | L45: =C45 -> 1031066
B46: =data!C47 -> 45199 | C46: =data!G47 -> 999496 | D46: =data!H47 -> -13479 | E46: =data!I47 -> -18699 | F46: =C46-C45 -> -31570 | G46: =D46+E46 -> -32178 | H46: =B46 -> 45199 | I46: =C46-C34 -> -37713 | L46: =C46 -> 999496
B47: =data!C48 -> 45230 | C47: =data!G48 -> 1015409 | D47: =data!H48 -> 26423 | E47: =data!I48 -> -10223 | F47: =C47-C46 -> 15913 | G47: =D47+E47 -> 16200 | H47: =B47 -> 45230 | I47: =C47-C35 -> 7355 | L47: =C47 -> 1015409
B48: =data!C49 -> 45260 | C48: =data!G49 -> 1042037 | D48: =data!H49 -> -72 | E48: =data!I49 -> 31522 | F48: =C48-C47 -> 26628 | G48: =D48+E48 -> 31450 | H48: =B48 -> 45260 | I48: =C48-C36 -> 23397 | L48: =C48 -> 1042037
B49: =data!C50 -> 45291 | C49: =data!G50 -> 1029295 | D49: =data!H50 -> -20070 | E49: =data!I50 -> 26322 | F49: =C49-C48 -> -12742 | G49: =D49+E49 -> 6252 | H49: =B49 -> 45291 | I49: =C49-C37 -> 34424 | L49: =C49 -> 1029295
B50: =data!C51 -> 45322 | C50: =data!G51 -> 1051432 | D50: =data!H51 -> 20322 | E50: =data!I51 -> 8114 | F50: =C50-C49 -> 22137 | G50: =D50+E50 -> 28436 | H50: =B50 -> 45322 | I50: =C50-C38 -> 21466 | J50: =SUM(D39:D50) -> 34770 | K50: =SUM(E39:E50) -> 14160 | L50: =C50 -> 1051432
B51: =data!C52 -> 45351 | C51: =data!G52 -> 1050448 | D51: =data!H52 -> 18907 | E51: =data!I52 -> -17577 | F51: =C51-C50 -> -984 | G51: =D51+E51 -> 1330 | H51: =B51 -> 45351 | I51: =C51-C39 -> 36618 | J51: =SUM(D40:D51) -> 49219 | K51: =SUM(E40:E51) -> 12260 | L51: =C51 -> 1050448
B52: =data!C53 -> 45382 | C52: =data!G53 -> 1068657 | D52: =data!H53 -> 13051 | E52: =data!I53 -> 2334 | F52: =C52-C51 -> 18209 | G52: =D52+E52 -> 15385 | H52: =B52 -> 45382 | I52: =C52-C40 -> 46678 | J52: =SUM(D41:D52) -> 78740 | K52: =SUM(E41:E52) -> -6975 | L52: =C52 -> 1068657
...
